Workbook

Sheet Monday
A1: Monday Availability
A2: Enter A = Available, B = Busy, P = PTO. Green rows mean everyone is available.
A4: Time | B4: Ghezlan | C4: Luka | D4: Bassem | E4: Andrea | F4: Alvaro J | G4: Alvaro P | H4: A Count | I4: All Free?
A5: 08:00-08:30 | B5: P | C5: A | D5: P | E5: B | G5: B | H5: =COUNTIF(B5:G5,"A") -> 1 | I5: =IF(H5=6,"YES","")
A6: 08:30-09:00 | B6: P | C6: A | D6: P | E6: B | G6: B | H6: =COUNTIF(B6:G6,"A") -> 1 | I6: =IF(H6=6,"YES","")
A7: 09:00-09:30 | B7: P | C7: A | D7: P | E7: B | G7: B | H7: =COUNTIF(B7:G7,"A") -> 1 | I7: =IF(H7=6,"YES","")
A8: 09:30-10:00 | B8: P | C8: A | D8: P | E8: B | G8: B | H8: =COUNTIF(B8:G8,"A") -> 1 | I8: =IF(H8=6,"YES","")
A9: 10:00-10:30 | B9: A | C9: A | D9: B | E9: B | G9: B | H9: =COUNTIF(B9:G9,"A") -> 2 | I9: =IF(H9=6,"YES","")
A10: 10:30-11:00 | B10: A | C10: A | D10: B | E10: B | G10: B | H10: =COUNTIF(B10:G10,"A") -> 2 | I10: =IF(H10=6,"YES","")
A11: 11:00-11:30 | B11: A | C11: A | D11: A | E11: B | G11: B | H11: =COUNTIF(B11:G11,"A") -> 3 | I11: =IF(H11=6,"YES","")
A12: 11:30-12:00 | B12: A | C12: A | D12: A | E12: B | G12: B | H12: =COUNTIF(B12:G12,"A") -> 3 | I12: =IF(H12=6,"YES","")
A13: 12:00-12:30 | B13: B | C13: A | D13: A | E13: B | G13: B | H13: =COUNTIF(B13:G13,"A") -> 2 | I13: =IF(H13=6,"YES","")
A14: 12:30-13:00 | B14: B | C14: A | D14: A | E14: B | G14: A | H14: =COUNTIF(B14:G14,"A") -> 3 | I14: =IF(H14=6,"YES","")
A15: 13:00-13:30 | B15: B | C15: A | D15: A | E15: B | G15: A | H15: =COUNTIF(B15:G15,"A") -> 3 | I15: =IF(H15=6,"YES","")
A16: 13:30-14:00 | B16: A | C16: A | D16: A | E16: B | G16: A | H16: =COUNTIF(B16:G16,"A") -> 4 | I16: =IF(H16=6,"YES","")
... A24: 17:30-18:00 | B24: A | C24: A | D24: A | E24: B | G24: B | H24: =COUNTIF(B24:G24,"A") -> 3 | I24: =IF(H24=6,"YES","")

Sheet Tuesday
A1: Tuesday Availability
A2: Enter A = Available, B = Busy, P = PTO. Green rows mean everyone is available.
A4: Time | B4: Ghezlan | C4: Luka | D4: Bassem | E4: Andrea | F4: Alvaro J | G4: Alvaro P | H4: A Count | I4: All Free?
A5: 08:00-08:30 | B5: P | C5: P | D5: P | G5: B | H5: =COUNTIF(B5:G5,"A") -> 0 | I5: =IF(H5=6,"YES","")
A6: 08:30-09:00 | B6: P | C6: P | D6: P | G6: B | H6: =COUNTIF(B6:G6,"A") -> 0 | I6: =IF(H6=6,"YES","")
A7: 09:00-09:30 | B7: P | C7: P | D7: P | G7: B | H7: =COUNTIF(B7:G7,"A") -> 0 | I7: =IF(H7=6,"YES","")
A8: 09:30-10:00 | B8: P | C8: P | D8: P | G8: B | H8: =COUNTIF(B8:G8,"A") -> 0 | I8: =IF(H8=6,"YES","")
A9: 10:00-10:30 | B9: P | C9: P | D9: A | G9: B | H9: =COUNTIF(B9:G9,"A") -> 1 | I9: =IF(H9=6,"YES","")
A10: 10:30-11:00 | B10: B | C10: P | D10: A | E10: A | G10: B | H10: =COUNTIF(B10:G10,"A") -> 2 | I10: =IF(H10=6,"YES","")
A11: 11:00-11:30 | B11: B | C11: P | D11: A | E11: A | G11: A | H11: =COUNTIF(B11:G11,"A") -> 3 | I11: =IF(H11=6,"YES","")
A12: 11:30-12:00 | B12: B | C12: P | D12: A | E12: A | G12: A | H12: =COUNTIF(B12:G12,"A") -> 3 | I12: =IF(H12=6,"YES","")
A13: 12:00-12:30 | B13: A | C13: P | D13: A | E13: A | G13: B | H13: =COUNTIF(B13:G13,"A") -> 3 | I13: =IF(H13=6,"YES","")
A14: 12:30-13:00 | B14: A | C14: P | D14: A | E14: A | G14: B | H14: =COUNTIF(B14:G14,"A") -> 3 | I14: =IF(H14=6,"YES","")
A15: 13:00-13:30 | B15: A | C15: P | D15: A | E15: A | G15: B | H15: =COUNTIF(B15:G15,"A") -> 3 | I15: =IF(H15=6,"YES","")
A16: 13:30-14:00 | B16: A | C16: P | D16: A | E16: A | G16: B | H16: =COUNTIF(B16:G16,"A") -> 3 | I16: =IF(H16=6,"YES","")
A17: 14:00-14:30 | B17: A | C17: P | D17: A | E17: A | G17: B | H17: =COUNTIF(B17:G17,"A") -> 3 | I17: =IF(H17=6,"YES","")
A18: 14:30-15:00 | B18: A | C18: A | D18: A | E18: A | G18: B | H18: =COUNTIF(B18:G18,"A") -> 4 | I18: =IF(H18=6,"YES","")
A19: 15:00-15:30 | B19: A | C19: A | D19: A | G19: B | H19: =COUNTIF(B19:G19,"A") -> 3 | I19: =IF(H19=6,"YES","")
A20: 15:30-16:00 | B20: A | C20: A | D20: A | G20: B | H20: =COUNTIF(B20:G20,"A") -> 3 | I20: =IF(H20=6,"YES","")
A21: 16:00-16:30 | B21: A | C21: A | D21: A | G21: B | H21: =COUNTIF(B21:G21,"A") -> 3 | I21: =IF(H21=6,"YES","")
A22: 16:30-17:00 | B22: A | C22: A | D22: A | G22: B | H22: =COUNTIF(B22:G22,"A") -> 3 | I22: =IF(H22=6,"YES","")
A23: 17:00-17:30 | B23: A | C23: A | D23: A | G23: A | H23: =COUNTIF(B23:G23,"A") -> 4 | I23: =IF(H23=6,"YES","")
A24: 17:30-18:00 | B24: A | C24: A | D24: A | G24: A | H24: =COUNTIF(B24:G24,"A") -> 4 | I24: =IF(H24=6,"YES","")

Sheet Wednesday
A1: Wednesday Availability
A2: Enter A = Available, B = Busy, P = PTO. Green rows mean everyone is available.
A4: Time | B4: Ghezlan | C4: Luka | D4: Bassem | E4: Andrea | F4: Alvaro J | G4: Alvaro P | H4: A Count | I4: All Free?
A5: 08:00-08:30 | B5: P | C5: A | D5: P | G5: B | H5: =COUNTIF(B5:G5,"A") -> 1 | I5: =IF(H5=6,"YES","")
A6: 08:30-09:00 | B6: P | C6: A | D6: P | G6: B | H6: =COUNTIF(B6:G6,"A") -> 1 | I6: =IF(H6=6,"YES","")
A7: 09:00-09:30 | B7: P | C7: A | D7: P | G7: B | H7: =COUNTIF(B7:G7,"A") -> 1 | I7: =IF(H7=6,"YES","")
A8: 09:30-10:00 | B8: P | C8: A | D8: P | G8: B | H8: =COUNTIF(B8:G8,"A") -> 1 | I8: =IF(H8=6,"YES","")
A9: 10:00-10:30 | B9: A | C9: A | D9: P | G9: B | H9: =COUNTIF(B9:G9,"A") -> 2 | I9: =IF(H9=6,"YES","")
A10: 10:30-11:00 | B10: A | C10: A | D10: P | E10: A | G10: B | H10: =COUNTIF(B10:G10,"A") -> 3 | I10: =IF(H10=6,"YES","")
A11: 11:00-11:30 | B11: A | C11: A | D11: A | E11: A | G11: A | H11: =COUNTIF(B11:G11,"A") -> 5 | I11: =IF(H11=6,"YES","")
A12: 11:30-12:00 | B12: A | C12: A | D12: B | E12: A | G12: A | H12: =COUNTIF(B12:G12,"A") -> 4 | I12: =IF(H12=6,"YES","")
A13: 12:00-12:30 | B13: B | C13: B | D13: B | G13: A | H13: =COUNTIF(B13:G13,"A") -> 1 | I13: =IF(H13=6,"YES","")
A14: 12:30-13:00 | B14: B | C14: B | D14: B | G14: A | H14: =COUNTIF(B14:G14,"A") -> 1 | I14: =IF(H14=6,"YES","")
A15: 13:00-13:30 | B15: B | C15: B | D15: B | G15: A | H15: =COUNTIF(B15:G15,"A") -> 1 | I15: =IF(H15=6,"YES","")
A16: 13:30-14:00 | B16: B | C16: A | D16: A | E16: A | G16: A | H16: =COUNTIF(B16:G16,"A") -> 4 | I16: =IF(H16=6,"YES","")
A17: 14:00-14:30 | B17: B | C17: A | D17: A | E17: A | G17: B | H17: =COUNTIF(B17:G17,"A") -> 3 | I17: =IF(H17=6,"YES","")
A18: 14:30-15:00 | B18: B | C18: A | D18: A | E18: A | G18: B | H18: =COUNTIF(B18:G18,"A") -> 3 | I18: =IF(H18=6,"YES","")
A19: 15:00-15:30 | B19: A | C19: A | D19: B | E19: A | G19: B | H19: =COUNTIF(B19:G19,"A") -> 3 | I19: =IF(H19=6,"YES","")
A20: 15:30-16:00 | B20: A | C20: A | D20: B | E20: A | G20: A | H20: =COUNTIF(B20:G20,"A") -> 4 | I20: =IF(H20=6,"YES","")
A21: 16:00-16:30 | B21: A | C21: A | D21: B | E21: A | G21: A | H21: =COUNTIF(B21:G21,"A") -> 4 | I21: =IF(H21=6,"YES","")
A22: 16:30-17:00 | B22: A | C22: A | D22: B | E22: A | G22: B | H22: =COUNTIF(B22:G22,"A") -> 3 | I22: =IF(H22=6,"YES","")
A23: 17:00-17:30 | B23: A | C23: A | D23: B | E23: A | G23: B | H23: =COUNTIF(B23:G23,"A") -> 3 | I23: =IF(H23=6,"YES","")
A24: 17:30-18:00 | B24: A | C24: A | D24: B | E24: A | G24: B | H24: =COUNTIF(B24:G24,"A") -> 3 | I24: =IF(H24=6,"YES","")

Sheet Thursday
A1: Thursday Availability
A2: Enter A = Available, B = Busy, P = PTO. Green rows mean everyone is available.
A4: Time | B4: Ghezlan | C4: Luka | D4: Bassem | E4: Andrea | F4: Alvaro J | G4: Alvaro P | H4: A Count | I4: All Free?
A5: 08:00-08:30 | B5: P | C5: A | D5: P | G5: B | H5: =COUNTIF(B5:G5,"A") -> 1 | I5: =IF(H5=6,"YES","")
A6: 08:30-09:00 | B6: P | C6: A | D6: P | G6: B | H6: =COUNTIF(B6:G6,"A") -> 1 | I6: =IF(H6=6,"YES","")
A7: 09:00-09:30 | B7: P | C7: A | D7: P | G7: B | H7: =COUNTIF(B7:G7,"A") -> 1 | I7: =IF(H7=6,"YES","")
A8: 09:30-10:00 | B8: P | C8: A | D8: P | G8: B | H8: =COUNTIF(B8:G8,"A") -> 1 | I8: =IF(H8=6,"YES","")
A9: 10:00-10:30 | B9: A | C9: A | D9: A | G9: B | H9: =COUNTIF(B9:G9,"A") -> 3 | I9: =IF(H9=6,"YES","")
A10: 10:30-11:00 | B10: A | C10: B | D10: A | G10: B | H10: =COUNTIF(B10:G10,"A") -> 2 | I10: =IF(H10=6,"YES","")
A11: 11:00-11:30 | B11: A | C11: B | D11: A | G11: B | H11: =COUNTIF(B11:G11,"A") -> 2 | I11: =IF(H11=6,"YES","")
A12: 11:30-12:00 | B12: A | C12: B | D12: B | G12: B | H12: =COUNTIF(B12:G12,"A") -> 1 | I12: =IF(H12=6,"YES","")
A13: 12:00-12:30 | B13: A | C13: A | D13: B | E13: A | G13: A | H13: =COUNTIF(B13:G13,"A") -> 4 | I13: =IF(H13=6,"YES","")
A14: 12:30-13:00 | B14: A | C14: A | D14: B | E14: A | G14: A | H14: =COUNTIF(B14:G14,"A") -> 4 | I14: =IF(H14=6,"YES","")
A15: 13:00-13:30 | B15: A | C15: A | D15: B | E15: A | G15: A | H15: =COUNTIF(B15:G15,"A") -> 4 | I15: =IF(H15=6,"YES","")
A16: 13:30-14:00 | B16: A | C16: A | D16: B | E16: A | G16: A | H16: =COUNTIF(B16:G16,"A") -> 4 | I16: =IF(H16=6,"YES","")
A17: 14:00-14:30 | B17: A | C17: A | D17: B | E17: A | G17: A | H17: =COUNTIF(B17:G17,"A") -> 4 | I17: =IF(H17=6,"YES","")
A18: 14:30-15:00 | B18: A | C18: A | D18: B | E18: A | G18: B | H18: =COUNTIF(B18:G18,"A") -> 3 | I18: =IF(H18=6,"YES","")
A19: 15:00-15:30 | B19: B | C19: A | D19: A | E19: A | G19: A | H19: =COUNTIF(B19:G19,"A") -> 4 | I19: =IF(H19=6,"YES","")
A20: 15:30-16:00 | B20: B | C20: A | D20: A | E20: A | G20: A | H20: =COUNTIF(B20:G20,"A") -> 4 | I20: =IF(H20=6,"YES","")
A21: 16:00-16:30 | B21: B | C21: A | D21: A | E21: A | G21: A | H21: =COUNTIF(B21:G21,"A") -> 4 | I21: =IF(H21=6,"YES","")
A22: 16:30-17:00 | B22: A | C22: A | D22: A | E22: A | G22: A | H22: =COUNTIF(B22:G22,"A") -> 5 | I22: =IF(H22=6,"YES","")
A23: 17:00-17:30 | B23: A | C23: A | D23: A | E23: A | G23: A | H23: =COUNTIF(B23:G23,"A") -> 5 | I23: =IF(H23=6,"YES","")
A24: 17:30-18:00 | B24: A | C24: A | D24: B | E24: A | G24: A | H24: =COUNTIF(B24:G24,"A") -> 4 | I24: =IF(H24=6,"YES","")

Sheet Friday
A1: Friday Availability
A2: Enter A = Available, B = Busy, P = PTO. Green rows mean everyone is available.
A4: Time | B4: Ghezlan | C4: Luka | D4: Bassem | E4: Andrea | F4: Alvaro J | G4: Alvaro P | H4: A Count | I4: All Free?
A5: 08:00-08:30 | B5: P | C5: B | D5: P | G5: B | H5: =COUNTIF(B5:G5,"A") -> 0 | I5: =IF(H5=6,"YES","")
A6: 08:30-09:00 | B6: P | C6: B | D6: P | G6: B | H6: =COUNTIF(B6:G6,"A") -> 0 | I6: =IF(H6=6,"YES","")
A7: 09:00-09:30 | B7: P | C7: B | D7: P | G7: B | H7: =COUNTIF(B7:G7,"A") -> 0 | I7: =IF(H7=6,"YES","")
A8: 09:30-10:00 | B8: P | C8: B | D8: P | G8: B | H8: =COUNTIF(B8:G8,"A") -> 0 | I8: =IF(H8=6,"YES","")
A9: 10:00-10:30 | B9: A | C9: B | D9: A | G9: B | H9: =COUNTIF(B9:G9,"A") -> 2 | I9: =IF(H9=6,"YES","")
A10: 10:30-11:00 | B10: A | C10: B | D10: A | E10: A | G10: B | H10: =COUNTIF(B10:G10,"A") -> 3 | I10: =IF(H10=6,"YES","")
A11: 11:00-11:30 | B11: A | C11: B | D11: A | E11: A | G11: A | H11: =COUNTIF(B11:G11,"A") -> 4 | I11: =IF(H11=6,"YES","")
A12: 11:30-12:00 | B12: A | C12: B | D12: B | E12: A | G12: A | H12: =COUNTIF(B12:G12,"A") -> 3 | I12: =IF(H12=6,"YES","")
A13: 12:00-12:30 | B13: A | C13: A | D13: B | E13: A | G13: A | H13: =COUNTIF(B13:G13,"A") -> 4 | I13: =IF(H13=6,"YES","")
A14: 12:30-13:00 | B14: A | C14: A | D14: B | E14: A | G14: A | H14: =COUNTIF(B14:G14,"A") -> 4 | I14: =IF(H14=6,"YES","")
A15: 13:00-13:30 | B15: A | C15: A | D15: B | E15: A | G15: B | H15: =COUNTIF(B15:G15,"A") -> 3 | I15: =IF(H15=6,"YES","")
A16: 13:30-14:00 | B16: A | C16: A | D16: A | E16: A | G16: B | H16: =COUNTIF(B16:G16,"A") -> 4 | I16: =IF(H16=6,"YES","")
A17: 14:00-14:30 | B17: A | C17: A | D17: A | E17: A | G17: B | H17: =COUNTIF(B17:G17,"A") -> 4 | I17: =IF(H17=6,"YES","")
A18: 14:30-15:00 | B18: A | C18: A | D18: A | E18: A | G18: B | H18: =COUNTIF(B18:G18,"A") -> 4 | I18: =IF(H18=6,"YES","")
A19: 15:00-15:30 | B19: A | C19: B | D19: A | G19: B | H19: =COUNTIF(B19:G19,"A") -> 2 | I19: =IF(H19=6,"YES","")
A20: 15:30-16:00 | B20: A | C20: B | D20: A | G20: B | H20: =COUNTIF(B20:G20,"A") -> 2 | I20: =IF(H20=6,"YES","")
A21: 16:00-16:30 | B21: B | C21: B | D21: B | G21: B | H21: =COUNTIF(B21:G21,"A") -> 0 | I21: =IF(H21=6,"YES","")
A22: 16:30-17:00 | B22: B | C22: A | D22: B | E22: A | G22: A | H22: =COUNTIF(B22:G22,"A") -> 3 | I22: =IF(H22=6,"YES","")
A23: 17:00-17:30 | B23: B | C23: A | D23: B | E23: A | G23: A | H23: =COUNTIF(B23:G23,"A") -> 3 | I23: =IF(H23=6,"YES","")
A24: 17:30-18:00 | B24: B | C24: A | D24: B | E24: A | G24: A | H24: =COUNTIF(B24:G24,"A") -> 3 | I24: =IF(H24=6,"YES","")

Sheet Best Slots
A1: Best Common Free Slots
A2: This sheet updates from the day tabs. Use A = Available, B = Busy, P = PTO.
A4: Day | B4: Time | C4: Available Count | D4: All 6 Free? | E4: Good Slot? | G4: Legend
A5: Monday | B5: 08:00-08:30 | C5: =Monday!H5 -> 1 | D5: =IF(C5=6,"YES","") | E5: =IF(C5>=4,"YES","") | G5: A | H5: Available
A6: Monday | B6: 08:30-09:00 | C6: =Monday!H6 -> 1 | D6: =IF(C6=6,"YES","") | E6: =IF(C6>=4,"YES","") | G6: B | H6: Busy
A7: Monday | B7: 09:00-09:30 | C7: =Monday!H7 -> 1 | D7: =IF(C7=6,"YES","") | E7: =IF(C7>=4,"YES","") | G7: P | H7: PTO / Out
A8: Monday | B8: 09:30-10:00 | C8: =Monday!H8 -> 1 | D8: =IF(C8=6,"YES","") | E8: =IF(C8>=4,"YES","")
A9: Monday | B9: 10:00-10:30 | C9: =Monday!H9 -> 2 | D9: =IF(C9=6,"YES","") | E9: =IF(C9>=4,"YES","")
A10: Monday | B10: 10:30-11:00 | C10: =Monday!H10 -> 2 | D10: =IF(C10=6,"YES","") | E10: =IF(C10>=4,"YES","")
A11: Monday | B11: 11:00-11:30 | C11: =Monday!H11 -> 3 | D11: =IF(C11=6,"YES","") | E11: =IF(C11>=4,"YES","")
A12: Monday | B12: 11:30-12:00 | C12: =Monday!H12 -> 3 | D12: =IF(C12=6,"YES","") | E12: =IF(C12>=4,"YES","")
A13: Monday | B13: 12:00-12:30 | C13: =Monday!H13 -> 2 | D13: =IF(C13=6,"YES","") | E13: =IF(C13>=4,"YES","")
A14: Monday | B14: 12:30-13:00 | C14: =Monday!H14 -> 3 | D14: =IF(C14=6,"YES","") | E14: =IF(C14>=4,"YES","")
A15: Monday | B15: 13:00-13:30 | C15: =Monday!H15 -> 3 | D15: =IF(C15=6,"YES","") | E15: =IF(C15>=4,"YES","")
A16: Monday | B16: 13:30-14:00 | C16: =Monday!H16 -> 4 | D16: =IF(C16=6,"YES","") | E16: =IF(C16>=4,"YES","") -> YES
A17: Monday | B17: 14:00-14:30 | C17: =Monday!H17 -> 4 | D17: =IF(C17=6,"YES","") | E17: =IF(C17>=4,"YES","") -> YES
A18: Monday | B18: 14:30-15:00 | C18: =Monday!H18 -> 4 | D18: =IF(C18=6,"YES","") | E18: =IF(C18>=4,"YES","") -> YES
A19: Monday | B19: 15:00-15:30 | C19: =Monday!H19 -> 3 | D19: =IF(C19=6,"YES","") | E19: =IF(C19>=4,"YES","")
... A24: Monday | B24: 17:30-18:00 | C24: =Monday!H24 -> 3 | D24: =IF(C24=6,"YES","") | E24: =IF(C24>=4,"YES","")
A25: Tuesday | B25: 08:00-08:30 | C25: =Tuesday!H5 -> 0 | D25: =IF(C25=6,"YES","") | E25: =IF(C25>=4,"YES","")
A26: Tuesday | B26: 08:30-09:00 | C26: =Tuesday!H6 -> 0 | D26: =IF(C26=6,"YES","") | E26: =IF(C26>=4,"YES","")
A27: Tuesday | B27: 09:00-09:30 | C27: =Tuesday!H7 -> 0 | D27: =IF(C27=6,"YES","") | E27: =IF(C27>=4,"YES","")
A28: Tuesday | B28: 09:30-10:00 | C28: =Tuesday!H8 -> 0 | D28: =IF(C28=6,"YES","") | E28: =IF(C28>=4,"YES","")
A29: Tuesday | B29: 10:00-10:30 | C29: =Tuesday!H9 -> 1 | D29: =IF(C29=6,"YES","") | E29: =IF(C29>=4,"YES","")
A30: Tuesday | B30: 10:30-11:00 | C30: =Tuesday!H10 -> 2 | D30: =IF(C30=6,"YES","") | E30: =IF(C30>=4,"YES","")
A31: Tuesday | B31: 11:00-11:30 | C31: =Tuesday!H11 -> 3 | D31: =IF(C31=6,"YES","") | E31: =IF(C31>=4,"YES","")
A32: Tuesday | B32: 11:30-12:00 | C32: =Tuesday!H12 -> 3 | D32: =IF(C32=6,"YES","") | E32: =IF(C32>=4,"YES","")
A33: Tuesday | B33: 12:00-12:30 | C33: =Tuesday!H13 -> 3 | D33: =IF(C33=6,"YES","") | E33: =IF(C33>=4,"YES","")
A34: Tuesday | B34: 12:30-13:00 | C34: =Tuesday!H14 -> 3 | D34: =IF(C34=6,"YES","") | E34: =IF(C34>=4,"YES","")
A35: Tuesday | B35: 13:00-13:30 | C35: =Tuesday!H15 -> 3 | D35: =IF(C35=6,"YES","") | E35: =IF(C35>=4,"YES","")
A36: Tuesday | B36: 13:30-14:00 | C36: =Tuesday!H16 -> 3 | D36: =IF(C36=6,"YES","") | E36: =IF(C36>=4,"YES","")
... A44: Tuesday | B44: 17:30-18:00 | C44: =Tuesday!H24 -> 4 | D44: =IF(C44=6,"YES","") | E44: =IF(C44>=4,"YES","") -> YES
A45: Wednesday | B45: 08:00-08:30 | C45: =Wednesday!H5 -> 1 | D45: =IF(C45=6,"YES","") | E45: =IF(C45>=4,"YES","")
A46: Wednesday | B46: 08:30-09:00 | C46: =Wednesday!H6 -> 1 | D46: =IF(C46=6,"YES","") | E46: =IF(C46>=4,"YES","")
A47: Wednesday | B47: 09:00-09:30 | C47: =Wednesday!H7 -> 1 | D47: =IF(C47=6,"YES","") | E47: =IF(C47>=4,"YES","")
A48: Wednesday | B48: 09:30-10:00 | C48: =Wednesday!H8 -> 1 | D48: =IF(C48=6,"YES","") | E48: =IF(C48>=4,"YES","")
A49: Wednesday | B49: 10:00-10:30 | C49: =Wednesday!H9 -> 2 | D49: =IF(C49=6,"YES","") | E49: =IF(C49>=4,"YES","")
A50: Wednesday | B50: 10:30-11:00 | C50: =Wednesday!H10 -> 3 | D50: =IF(C50=6,"YES","") | E50: =IF(C50>=4,"YES","")
A51: Wednesday | B51: 11:00-11:30 | C51: =Wednesday!H11 -> 5 | D51: =IF(C51=6,"YES","") | E51: =IF(C51>=4,"YES","") -> YES
A52: Wednesday | B52: 11:30-12:00 | C52: =Wednesday!H12 -> 4 | D52: =IF(C52=6,"YES","") | E52: =IF(C52>=4,"YES","") -> YES
...
